Workbook

Sheet Income Statement
B3: Sky Limited Company
A4: #
B5: Income Statement | C5: Actuals | E5: Expected
B6: Years | C6: 2023A | D6: 2024A | E6: 2025P | F6: 2026P | G6: 2027P | H6: 2028P | I6: 2029P | J6: 2030P
B8: Sales | C8: 10232 | D8: 10396 | E8: =D8*(1+E25) -> 11435.6 | F8: =E8*(1+F25) -> 12579.16 | G8: =F8*(1+G25) -> 13837.076 | H8: =G8*(1+H25) -> 15220.784 | I8: =H8*(1+I25) -> 16742.862 | J8: =I8*(1+J25) -> 18417.148
B9: COGS | C9: 5113 | D9: 5174 | E9: =E8*E26 -> 5717.8 | F9: =F8*F26 -> 6163.7884 | G9: =G8*G26 -> 6641.7965 | H9: =H8*H26 -> 7153.7683 | I9: =I8*I26 -> 7701.7165 | J9: =J8*J26 -> 8287.7167
B10: Gross Profit | C10: =C8-C9 -> 5119 | D10: =D8-D9 -> 5222 | E10: =E8-E9 -> 5717.8 | F10: =F8-F9 -> 6415.3716 | G10: =G8-G9 -> 7195.2795 | H10: =H8-H9 -> 8067.0153 | I10: =I8-I9 -> 9041.1455 | J10: =J8-J9 -> 10129.431
B12: Selling & General expenses | C12: 5343 | D12: 5334 | E12: =E8*E27 -> 5832.156 | F12: =F8*F27 -> 6163.7884 | G12: =G8*G27 -> 6503.4257 | H12: =H8*H27 -> 6849.3526 | I12: =I8*I27 -> 7199.4306 | J12: =J8*J27 -> 7551.0307
B13: EBITDA | C13: =C10-C12 -> -224 | D13: =D10-D12 -> -112 | E13: =E10-E12 -> -114.356 | F13: =F10-F12 -> 251.5832 | G13: =G10-G12 -> 691.8538 | H13: =H10-H12 -> 1217.6627 | I13: =I10-I12 -> 1841.7148 | J13: =J10-J12 -> 2578.4007
B15: Depreciation | C15: N/A | D15: N/A | E15: - | F15: - | G15: - | H15: - | I15: - | J15: -
B16: EBIT | C16: =C13 -> -224 | D16: =D13 -> -112 | E16: =E13 -> -114.356 | F16: =F13 -> 251.5832 | G16: =G13 -> 691.8538 | H16: =H13 -> 1217.6627 | I16: =I13 -> 1841.7148 | J16: =J13 -> 2578.4007
B17: Interest Expense | C17: 310 | D17: 406 | E17: =E28 -> 350 | F17: =F28 -> 350 | G17: =G28 -> 350 | H17: =H28 -> 350 | I17: =I28 -> 350 | J17: =J28 -> 350
B19: EBT | C19: =C16-C17 -> -534 | D19: =D16-D17 -> -518 | E19: =E16-E17 -> -464.356 | F19: =F16-F17 -> -98.4168 | G19: =G16-G17 -> 341.8538 | H19: =H16-H17 -> 867.66269 | I19: =I16-I17 -> 1491.7148 | J19: =J16-J17 -> 2228.4007
B21: Tax | C21: 22 | D21: -3 | E21: =E19*E29 -> -92.8712 | F21: =F19*F29 -> -19.68336 | G21: =G19*G29 -> 68.37076 | H21: =H19*H29 -> 173.53254 | I21: =I19*I29 -> 298.34296 | J21: =J19*J29 -> 445.68015
B22: Net Profit | C22: =C19-C21 -> -556 | D22: =D19-D21 -> -515 | E22: =E19-E21 -> -371.4848 | F22: =F19-F21 -> -78.73344 | G22: =G19-G21 -> 273.48304 | H22: =H19-H21 -> 694.13015 | I22: =I19-I21 -> 1193.3719 | J22: =J19-J21 -> 1782.7206
B24: Assumptions
A25: 1) | B25: Revenue growth to 10 % | C25: 0.1 | D25: 0.1 | E25: 0.1 | F25: 0.1 | G25: 0.1 | H25: 0.1 | I25: 0.1 | J25: 0.1
A26: 2) | B26: COGS as revenue of % to 55% | C26: =C9/C8 -> 0.4997068 | D26: =D9/D8 -> 0.49769142 | E26: 0.5 | F26: 0.49 | G26: 0.48 | H26: 0.47 | I26: 0.46 | J26: 0.45
A27: 3) | B27: SG&A Expenses as a % Revenue 60% | C27: =C12/C8 -> 0.5221853 | D27: =D12/D8 -> 0.51308195 | E27: 0.51 | F27: 0.49 | G27: 0.47 | H27: 0.45 | I27: 0.43 | J27: 0.41
A28: 4) | B28: Interest Expense as a 350 every year | E28: 350 | F28: 350 | G28: 350 | H28: 350 | I28: 350 | J28: 350
A29: 5) | B29: Tax | E29: 0.2 | F29: =E29 -> 0.2 | G29: =F29 -> 0.2 | H29: =G29 -> 0.2 | I29: =H29 -> 0.2 | J29: =I29 -> 0.2

Sheet Balance sheet
B2: Sky Limited Company
A4: # | B4: Balance Sheet
B5: Years | C5: 2023 | D5: 2024
B7: Non-current assets
B8: Goodwill | C8: 88 | D8: 88
B9: Intangible assets | C9: 503 | D9: 545
B10: Property, plant & equipment | C10: 800 | D10: 773
B11: Right-of-use assets | C11: 200 | D11: 201
B12: Investment in subsidiaries | C12: 2557 | D12: 2459
B13: Investments in JVs & associates | C13: — | D13: —
B14: Deferred tax assets | C14: 22 | D14: 15
B15: Cost to obtain customer contracts | C15: 58 | D15: 68
B16: Costs-to-fulfil customer contracts | C16: — | D16: 1
B17: Trade & other receivables | C17: 11911 | D17: 9051
B18: Derivative financial assets | C18: 21 | D18: 11
B19: Minority equity investments | C19: 4 | D19: 4
B21: Total non-current assets | C21: 16164 | D21: 13216
B23: Current assets
B24: Inventories | C24: 1611 | D24: 1471
B25: Trade & other receivables | C25: 3526 | D25: 4679
B26: Cash & cash equivalents | C26: 178 | D26: 181
B27: Derivative financial assets | C27: 38 | D27: 32
B28: Current tax assets | C28: 63 | D28: 55
B30: Total current assets | C30: 5416 | D30: 6418
B32: Total Assets | C32: 21580 | D32: 19634
B34: Current liabilities
B35: Trade & other payables | C35: 12414 | D35: 12215
B36: Lease liabilities | C36: 27 | D36: 36
B37: Provisions | C37: 15 | D37: 15
B38: Derivative financial liabilities | C38: 51 | D38: 34
B40: Total current liabilities | C40: 12507 | D40: 12300
B42: Non-current liabilities
B43: Trade & other payables | C43: 4094 | D43: 1330
B44: Lease liabilities | C44: 155 | D44: 156
B45: Provisions | C45: 3 | D45: 5
B46: Derivative financial liabilities | C46: 130 | D46: 9
B48: Total non-current liabilities | C48: 4382 | D48: 1500
B50: Share capital | C50: 10 | D50: 10
B51: Share premium | C51: 1 | D51: 886
B52: Reserves | C52: 4680 | D52: 4938
...

Sheet Ratio Analysis
B3: Sky Limited Company
B5: Ratio Analysis | E5: Forecasting
B6: Years | C6: 2023 | D6: 2024 | E6: 2025 | F6: 2026 | G6: 2027 | H6: 2028 | I6: 2029 | J6: 2030 | K6: Trendline | L6: Mean | M6: Median
B8: Sales Growth | C8: - | D8: ='Income Statement'!D8/'Income Statement'!C8-1 -> 0.016028147 | E8: ='Income Statement'!E8/'Income Statement'!D8-1 -> 0.1 | F8: ='Income Statement'!F8/'Income Statement'!E8-1 -> 0.1 | G8: ='Income Statement'!G8/'Income Statement'!F8-1 -> 0.1 | H8: ='Income Statement'!H8/'Income Statement'!G8-1 -> 0.1 | I8: ='Income Statement'!I8/'Income Statement'!H8-1 -> 0.1 | J8: ='Income Statement'!J8/'Income Statement'!I8-1 -> 0.1 | L8: =AVERAGE(D8:J8) -> 0.088004021 | M8: =MEDIAN(D8:J8) -> 0.1
B9: EBITDA Growth | C9: - | D9: ='Income Statement'!D13/'Income Statement'!C13-1 -> -0.5 | E9: ='Income Statement'!E13/'Income Statement'!D13-1 -> 0.021035714 | F9: ='Income Statement'!F13/'Income Statement'!E13-1 -> -3.2 | G9: ='Income Statement'!G13/'Income Statement'!F13-1 -> 1.75 | H9: ='Income Statement'!H13/'Income Statement'!G13-1 -> 0.76 | I9: ='Income Statement'!I13/'Income Statement'!H13-1 -> 0.5125 | J9: ='Income Statement'!J13/'Income Statement'!I13-1 -> 0.4 | L9: =AVERAGE(D9:J9) -> -0.036637755 | M9: =MEDIAN(D9:J9) -> 0.4
B10: EBIT Growth | C10: - | D10: ='Income Statement'!D16/'Income Statement'!C16-1 -> -0.5 | E10: ='Income Statement'!E16/'Income Statement'!D16-1 -> 0.021035714 | F10: ='Income Statement'!F16/'Income Statement'!E16-1 -> -3.2 | G10: ='Income Statement'!G16/'Income Statement'!F16-1 -> 1.75 | H10: ='Income Statement'!H16/'Income Statement'!G16-1 -> 0.76 | I10: ='Income Statement'!I16/'Income Statement'!H16-1 -> 0.5125 | J10: ='Income Statement'!J16/'Income Statement'!I16-1 -> 0.4 | L10: =AVERAGE(D10:J10) -> -0.036637755 | M10: =MEDIAN(D10:J10) -> 0.4
B11: Net Profit Growth | C11: - | D11: ='Income Statement'!D22/'Income Statement'!C22-1 -> -0.073741007 | E11: ='Income Statement'!E22/'Income Statement'!D22-1 -> -0.27867029 | F11: ='Income Statement'!F22/'Income Statement'!E22-1 -> -0.78805744 | G11: ='Income Statement'!G22/'Income Statement'!F22-1 -> -4.4735309 | H11: ='Income Statement'!H22/'Income Statement'!G22-1 -> 1.5381104 | I11: ='Income Statement'!I22/'Income Statement'!H22-1 -> 0.71923356 | J11: ='Income Statement'!J22/'Income Statement'!I22-1 -> 0.49385172 | L11: =AVERAGE(D11:J11) -> -0.408972 | M11: =MEDIAN(D11:J11) -> -0.073741007
B13: Gross Margin | C13: ='Income Statement'!C10/'Income Statement'!C8 -> 0.5002932 | D13: ='Income Statement'!D10/'Income Statement'!D8 -> 0.50230858 | E13: ='Income Statement'!E10/'Income Statement'!E8 -> 0.5 | F13: ='Income Statement'!F10/'Income Statement'!F8 -> 0.51 | G13: ='Income Statement'!G10/'Income Statement'!G8 -> 0.52 | H13: ='Income Statement'!H10/'Income Statement'!H8 -> 0.53 | I13: ='Income Statement'!I10/'Income Statement'!I8 -> 0.54 | J13: ='Income Statement'!J10/'Income Statement'!J8 -> 0.55 | L13: =AVERAGE(C13:J13) -> 0.51907522 | M13: =MEDIAN(C13:J13) -> 0.515
B14: EBITDA Margin | C14: ='Income Statement'!C13/'Income Statement'!C8 -> -0.021892103 | D14: ='Income Statement'!D13/'Income Statement'!D8 -> -0.010773374 | E14: ='Income Statement'!E13/'Income Statement'!E8 -> -0.01 | F14: ='Income Statement'!F13/'Income Statement'!F8 -> 0.02 | G14: ='Income Statement'!G13/'Income Statement'!G8 -> 0.05 | H14: ='Income Statement'!H13/'Income Statement'!H8 -> 0.08 | I14: ='Income Statement'!I13/'Income Statement'!I8 -> 0.11 | J14: ='Income Statement'!J13/'Income Statement'!J8 -> 0.14 | L14: =AVERAGE(C14:J14) -> 0.044666815 | M14: =MEDIAN(C14:J14) -> 0.035
B15: EBIT Margin | C15: ='Income Statement'!C16/'Income Statement'!C8 -> -0.021892103 | D15: ='Income Statement'!D16/'Income Statement'!D8 -> -0.010773374 | E15: ='Income Statement'!E16/'Income Statement'!E8 -> -0.01 | F15: ='Income Statement'!F16/'Income Statement'!F8 -> 0.02 | G15: ='Income Statement'!G16/'Income Statement'!G8 -> 0.05 | H15: ='Income Statement'!H16/'Income Statement'!H8 -> 0.08 | I15: ='Income Statement'!I16/'Income Statement'!I8 -> 0.11 | J15: ='Income Statement'!J16/'Income Statement'!J8 -> 0.14 | L15: =AVERAGE(C15:J15) -> 0.044666815 | M15: =MEDIAN(C15:J15) -> 0.035
B16: EBT Margin | C16: ='Income Statement'!C19/'Income Statement'!C8 -> -0.05218921 | D16: ='Income Statement'!D19/'Income Statement'!D8 -> -0.049826856 | E16: ='Income Statement'!E19/'Income Statement'!E8 -> -0.040606177 | F16: ='Income Statement'!F19/'Income Statement'!F8 -> -0.0078237975 | G16: ='Income Statement'!G19/'Income Statement'!G8 -> 0.024705639 | H16: ='Income Statement'!H19/'Income Statement'!H8 -> 0.057005126 | I16: ='Income Statement'!I19/'Income Statement'!I8 -> 0.089095569 | J16: ='Income Statement'!J19/'Income Statement'!J8 -> 0.12099597 | L16: =AVERAGE(C16:J16) -> 0.017669533 | M16: =MEDIAN(C16:J16) -> 0.0084409206
B17: Net Profit Margin | C17: ='Income Statement'!C22/'Income Statement'!C8 -> -0.054339328 | D17: ='Income Statement'!D22/'Income Statement'!D8 -> -0.049538284 | E17: ='Income Statement'!E22/'Income Statement'!E8 -> -0.032484942 | F17: ='Income Statement'!F22/'Income Statement'!F8 -> -0.006259038 | G17: ='Income Statement'!G22/'Income Statement'!G8 -> 0.019764511 | H17: ='Income Statement'!H22/'Income Statement'!H8 -> 0.045604101 | I17: ='Income Statement'!I22/'Income Statement'!I8 -> 0.071276455 | J17: ='Income Statement'!J22/'Income Statement'!J8 -> 0.096796778 | L17: =AVERAGE(C17:J17) -> 0.011352532 | M17: =MEDIAN(C17:J17) -> 0.0067527365
B19: Sales expenses% Sales | C19: ='Income Statement'!C12/'Income Statement'!C8 -> 0.5221853 | D19: ='Income Statement'!D12/'Income Statement'!D8 -> 0.51308195 | E19: ='Income Statement'!E12/'Income Statement'!E8 -> 0.51 | F19: ='Income Statement'!F12/'Income Statement'!F8 -> 0.49 | G19: ='Income Statement'!G12/'Income Statement'!G8 -> 0.47 | H19: ='Income Statement'!H12/'Income Statement'!H8 -> 0.45 | I19: ='Income Statement'!I12/'Income Statement'!I8 -> 0.43 | J19: ='Income Statement'!J12/'Income Statement'!J8 -> 0.41 | L19: =AVERAGE(C19:J19) -> 0.47440841 | M19: =MEDIAN(C19:J19) -> 0.48
B20: Depreciation % Sales | C20: 0 | D20: 0 | E20: 0 | F20: 0 | G20: 0 | H20: 0 | I20: 0 | J20: 0 | L20: =AVERAGE(C20:J20) -> 0 | M20: =MEDIAN(C20:J20) -> 0
B21: Operating income % Sales | C21: =C15 -> -0.021892103 | D21: =D15 -> -0.010773374 | E21: =E15 -> -0.01 | F21: =F15 -> 0.02 | G21: =G15 -> 0.05 | H21: =H15 -> 0.08 | I21: =I15 -> 0.11 | J21: =J15 -> 0.14 | L21: =AVERAGE(C21:J21) -> 0.044666815 | M21: =MEDIAN(C21:J21) -> 0.035
B23: Return on Capital employed | C23: ='Income Statement'!C16/SUM('Balance sheet'!C50:C52) -> -0.047751013 | D23: ='Income Statement'!D16/SUM('Balance sheet'!D50:D52) -> -0.019197806 | E23: - | F23: - | G23: - | H23: - | I23: - | J23: - | L23: =AVERAGE(C23:D23) -> -0.033474409 | M23: =MEDIAN(C23:D23) -> -0.033474409
B24: Return on Equity % | C24: ='Income Statement'!C22/SUM('Balance sheet'!C50:C52) -> -0.11852483 | D24: ='Income Statement'!D22/SUM('Balance sheet'!D50:D52) -> -0.088275626 | E24: - | F24: - | G24: - | H24: - | I24: - | J24: - | L24: =AVERAGE(C24:D24) -> -0.10340023 | M24: =MEDIAN(C24:D24) -> -0.10340023
B25: Interest Covered ratio | C25: ='Income Statement'!C16/'Income Statement'!C17 -> -0.72258065 | D25: ='Income Statement'!D16/'Income Statement'!D17 -> -0.27586207 | E25: ='Income Statement'!E16/'Income Statement'!E17 -> -0.32673143 | F25: ='Income Statement'!F16/'Income Statement'!F17 -> 0.71880914 | G25: ='Income Statement'!G16/'Income Statement'!G17 -> 1.9767251 | H25: ='Income Statement'!H16/'Income Statement'!H17 -> 3.4790363 | I25: ='Income Statement'!I16/'Income Statement'!I17 -> 5.2620423 | J25: ='Income Statement'!J16/'Income Statement'!J17 -> 7.3668593 | L25: =AVERAGE(C25:J25) -> 2.1847872 | M25: =MEDIAN(C25:J25) -> 1.3477671
B27: Debtors turnover ratio | C27: ='Income Statement'!C8/'Balance sheet'!C25 -> 2.9018718 | D27: ='Income Statement'!D8/'Balance sheet'!D25 -> 2.2218423 | E27: - | F27: - | G27: - | H27: - | I27: - | J27: - | L27: =AVERAGE(C27:D27) -> 2.561857 | M27: =MEDIAN(C27:D27) -> 2.561857
B28: Creditors turnover ratio | C28: ='Income Statement'!C9/'Balance sheet'!C35 -> 0.41187369 | D28: ='Income Statement'!D9/'Balance sheet'!D35 -> 0.42357757 | E28: - | F28: - | G28: - | H28: - | I28: - | J28: - | L28: =AVERAGE(C28:D28) -> 0.41772563 | M28: =MEDIAN(C28:D28) -> 0.41772563
B29: Inventory turnover ratio | C29: ='Income Statement'!C9/'Balance sheet'!C24 -> 3.1738051 | D29: ='Income Statement'!D9/'Balance sheet'!D24 -> 3.5173351 | E29: - | F29: - | G29: - | H29: - | I29: - | J29: - | L29: =AVERAGE(C29:D29) -> 3.3455701 | M29: =MEDIAN(C29:D29) -> 3.3455701
B30: Fixed Assets turnover ratio | C30: ='Income Statement'!C8/'Balance sheet'!C10 -> 12.79 | D30: ='Income Statement'!D8/'Balance sheet'!D10 -> 13.4489 | E30: - | F30: - | G30: - | H30: - | I30: - | J30: - | L30: =AVERAGE(C30:D30) -> 13.11945 | M30: =MEDIAN(C30:D30) -> 13.11945
B31: Capital turnover ratio | C31: ='Income Statement'!C8/SUM('Balance sheet'!C32-'Balance sheet'!C40) -> 1.1277417 | D31: ='Income Statement'!D8/SUM('Balance sheet'!D32-'Balance sheet'!D40) -> 1.4175075 | E31: - | F31: - | G31: - | H31: - | I31: - | J31: - | L31: =AVERAGE(C31:D31) -> 1.2726246 | M31: =MEDIAN(C31:D31) -> 1.2726246
B33: Debtors Day | C33: =365/C27 -> 125.78088 | D33: =365/D27 -> 164.27809 | E33: - | F33: - | G33: - | H33: - | I33: - | J33: - | L33: =AVERAGE(C33:D33) -> 145.02949 | M33: =MEDIAN(C33:D33) -> 145.02949
B34: Payable Day | C34: =365/C28 -> 886.19402 | D34: =365/D28 -> 861.70758 | E34: - | F34: - | G34: - | H34: - | I34: - | J34: - | L34: =AVERAGE(C34:D34) -> 873.9508 | M34: =MEDIAN(C34:D34) -> 873.9508
B35: Inventory Day | C35: =365/C29 -> 115.00391 | D35: =365/D29 -> 103.77174 | E35: - | F35: - | G35: - | H35: - | I35: - | J35: - | L35: =AVERAGE(C35:D35) -> 109.38783 | M35: =MEDIAN(C35:D35) -> 109.38783

Sheet Revenue Charts
B2: Sky Limited Company
B3: Revenue Performance – Charts & Visuals
B5: Sales - Forecasting | P5: Year Weight | Q5: Year | R5: EBITDA | S5: Net Profit
B6: Year Weight | C6: Year | D6: Sales | E6: Sales Growth | P6: 1 | Q6: 2023A | R6: ='Income Statement'!C13 -> -224 | S6: ='Income Statement'!C22 -> -556
B7: 1 | C7: 2023A | D7: ='Income Statement'!C8 -> 10232 | P7: =P6+1 -> 2 | Q7: 2024A | R7: ='Income Statement'!D13 -> -112 | S7: ='Income Statement'!D22 -> -515
B8: =B7+1 -> 2 | C8: 2024A | D8: ='Income Statement'!D8 -> 10396 | E8: =D8/D7-1 -> 0.016028147 | P8: =P7+1 -> 3 | Q8: 2025P | R8: ='Income Statement'!E13 -> -114.356 | S8: ='Income Statement'!E22 -> -371.4848
B9: =B8+1 -> 3 | C9: 2025P | D9: ='Income Statement'!E8 -> 11435.6 | E9: =D9/D8-1 -> 0.1 | P9: =P8+1 -> 4 | Q9: 2026P | R9: ='Income Statement'!F13 -> 251.5832 | S9: ='Income Statement'!F22 -> -78.73344
B10: =B9+1 -> 4 | C10: 2026P | D10: ='Income Statement'!F8 -> 12579.16 | E10: =D10/D9-1 -> 0.1 | P10: =P9+1 -> 5 | Q10: 2027P | R10: ='Income Statement'!G13 -> 691.8538 | S10: ='Income Statement'!G22 -> 273.48304
B11: =B10+1 -> 5 | C11: 2027P | D11: ='Income Statement'!G8 -> 13837.076 | E11: =D11/D10-1 -> 0.1 | P11: =P10+1 -> 6 | Q11: 2028P | R11: ='Income Statement'!H13 -> 1217.6627 | S11: ='Income Statement'!H22 -> 694.13015
B12: =B11+1 -> 6 | C12: 2028P | D12: ='Income Statement'!H8 -> 15220.784 | E12: =D12/D11-1 -> 0.1 | P12: =P11+1 -> 7 | Q12: 2029P | R12: ='Income Statement'!I13 -> 1841.7148 | S12: ='Income Statement'!I22 -> 1193.3719
B13: =B12+1 -> 7 | C13: 2029P | D13: ='Income Statement'!I8 -> 16742.862 | E13: =D13/D12-1 -> 0.1 | P13: =P12+1 -> 8 | Q13: 2030P | R13: ='Income Statement'!J13 -> 2578.4007 | S13: ='Income Statement'!J22 -> 1782.7206
B14: =B13+1 -> 8 | C14: 2030P | D14: ='Income Statement'!J8 -> 18417.148 | E14: =D14/D13-1 -> 0.1
B24: Year Weight | C24: Year | D24: Sales | P24: Year Weight | Q24: Year | R24: Revenue | S24: COGS | T24: Gross Profit
B25: 1 | C25: 2023A | D25: =D7 -> 10232 | P25: 1 | Q25: 2023A | R25: =D25 -> 10232 | S25: ='Income Statement'!C9 -> 5113 | T25: =R25-S25 -> 5119
B26: =B25+1 -> 2 | C26: 2024A | D26: =D8 -> 10396 | P26: =P25+1 -> 2 | Q26: 2024A | R26: =D26 -> 10396 | S26: ='Income Statement'!D9 -> 5174 | T26: =R26-S26 -> 5222
B27: =B26+1 -> 3 | C27: 2025P | D27: =D9 -> 11435.6 | P27: =P26+1 -> 3 | Q27: 2025P | R27: =D27 -> 11435.6 | S27: ='Income Statement'!E9 -> 5717.8 | T27: =R27-S27 -> 5717.8
B28: =B27+1 -> 4 | C28: 2026P | D28: =D10 -> 12579.16 | P28: =P27+1 -> 4 | Q28: 2026P | R28: =D28 -> 12579.16 | S28: ='Income Statement'!F9 -> 6163.7884 | T28: =R28-S28 -> 6415.3716
B29: =B28+1 -> 5 | C29: 2027P | D29: =D11 -> 13837.076 | P29: =P28+1 -> 5 | Q29: 2027P | R29: =D29 -> 13837.076 | S29: ='Income Statement'!G9 -> 6641.7965 | T29: =R29-S29 -> 7195.2795
B30: =B29+1 -> 6 | C30: 2028P | D30: =D12 -> 15220.784 | P30: =P29+1 -> 6 | Q30: 2028P | R30: =D30 -> 15220.784 | S30: ='Income Statement'!H9 -> 7153.7683 | T30: =R30-S30 -> 8067.0153
B31: =B30+1 -> 7 | C31: 2029P | D31: =D13 -> 16742.862 | P31: =P30+1 -> 7 | Q31: 2029P | R31: =D31 -> 16742.862 | S31: ='Income Statement'!I9 -> 7701.7165 | T31: =R31-S31 -> 9041.1455
B32: =B31+1 -> 8 | C32: 2030P | D32: =D14 -> 18417.148 | P32: =P31+1 -> 8 | Q32: 2030P | R32: =D32 -> 18417.148 | S32: ='Income Statement'!J9 -> 8287.7167 | T32: =R32-S32 -> 10129.431

Sheet Variance Analysis
B3: Sky Limited Company
B5: Variance Analysis
B8: Line Item | C8: 2023A - 2024A | D8: 2024A - 2025P | E8: 2025P - 2026P | F8: 2026P - 2027P | G8: 2027P - 2028P | H8: 2028P - 2029P | I8: 2029P - 2030P
B9: Sales | C9: ='Income Statement'!D8-'Income Statement'!C8 -> 164 | D9: ='Income Statement'!E8-'Income Statement'!D8 -> 1039.6 | E9: ='Income Statement'!F8-'Income Statement'!E8 -> 1143.56 | F9: ='Income Statement'!G8-'Income Statement'!F8 -> 1257.916 | G9: ='Income Statement'!H8-'Income Statement'!G8 -> 1383.7076 | H9: ='Income Statement'!I8-'Income Statement'!H8 -> 1522.0784 | I9: ='Income Statement'!J8-'Income Statement'!I8 -> 1674.2862
B10: COGS | C10: ='Income Statement'!D9-'Income Statement'!C9 -> 61 | D10: ='Income Statement'!E9-'Income Statement'!D9 -> 543.8 | E10: ='Income Statement'!F9-'Income Statement'!E9 -> 445.9884 | F10: ='Income Statement'!G9-'Income Statement'!F9 -> 478.00808 | G10: ='Income Statement'!H9-'Income Statement'!G9 -> 511.97181 | H10: ='Income Statement'!I9-'Income Statement'!H9 -> 547.94821 | I10: ='Income Statement'!J9-'Income Statement'!I9 -> 586.00017
B11: Gross Profit | C11: ='Income Statement'!D10-'Income Statement'!C10 -> 103 | D11: ='Income Statement'!E10-'Income Statement'!D10 -> 495.8 | E11: ='Income Statement'!F10-'Income Statement'!E10 -> 697.5716 | F11: ='Income Statement'!G10-'Income Statement'!F10 -> 779.90792 | G11: ='Income Statement'!H10-'Income Statement'!G10 -> 871.73579 | H11: ='Income Statement'!I10-'Income Statement'!H10 -> 974.13015 | I11: ='Income Statement'!J10-'Income Statement'!I10 -> 1088.286
B12: Selling & General expenses | C12: ='Income Statement'!D12-'Income Statement'!C12 -> -9 | D12: ='Income Statement'!E12-'Income Statement'!D12 -> 498.156 | E12: ='Income Statement'!F12-'Income Statement'!E12 -> 331.6324 | F12: ='Income Statement'!G12-'Income Statement'!F12 -> 339.63732 | G12: ='Income Statement'!H12-'Income Statement'!G12 -> 345.9269 | H12: ='Income Statement'!I12-'Income Statement'!H12 -> 350.07802 | I12: ='Income Statement'!J12-'Income Statement'!I12 -> 351.6001
B13: EBITDA | C13: ='Income Statement'!D13-'Income Statement'!C13 -> 112 | D13: ='Income Statement'!E13-'Income Statement'!D13 -> -2.356 | E13: ='Income Statement'!F13-'Income Statement'!E13 -> 365.9392 | F13: ='Income Statement'!G13-'Income Statement'!F13 -> 440.2706 | G13: ='Income Statement'!H13-'Income Statement'!G13 -> 525.80889 | H13: ='Income Statement'!I13-'Income Statement'!H13 -> 624.05213 | I13: ='Income Statement'!J13-'Income Statement'!I13 -> 736.68593
B14: EBIT | C14: ='Income Statement'!D16-'Income Statement'!C16 -> 112 | D14: ='Income Statement'!E16-'Income Statement'!D16 -> -2.356 | E14: ='Income Statement'!F16-'Income Statement'!E16 -> 365.9392 | F14: ='Income Statement'!G16-'Income Statement'!F16 -> 440.2706 | G14: ='Income Statement'!H16-'Income Statement'!G16 -> 525.80889 | H14: ='Income Statement'!I16-'Income Statement'!H16 -> 624.05213 | I14: ='Income Statement'!J16-'Income Statement'!I16 -> 736.68593
B15: Interest Expense | C15: ='Income Statement'!D17-'Income Statement'!C17 -> 96 | D15: ='Income Statement'!E17-'Income Statement'!D17 -> -56 | E15: ='Income Statement'!F17-'Income Statement'!E17 -> 0 | F15: ='Income Statement'!G17-'Income Statement'!F17 -> 0 | G15: ='Income Statement'!H17-'Income Statement'!G17 -> 0 | H15: ='Income Statement'!I17-'Income Statement'!H17 -> 0 | I15: ='Income Statement'!J17-'Income Statement'!I17 -> 0
B16: EBT | C16: ='Income Statement'!D19-'Income Statement'!C19 -> 16 | D16: ='Income Statement'!E19-'Income Statement'!D19 -> 53.644 | E16: ='Income Statement'!F19-'Income Statement'!E19 -> 365.9392 | F16: ='Income Statement'!G19-'Income Statement'!F19 -> 440.2706 | G16: ='Income Statement'!H19-'Income Statement'!G19 -> 525.80889 | H16: ='Income Statement'!I19-'Income Statement'!H19 -> 624.05213 | I16: ='Income Statement'!J19-'Income Statement'!I19 -> 736.68593
B17: Tax | C17: ='Income Statement'!D21-'Income Statement'!C21 -> -25 | D17: ='Income Statement'!E21-'Income Statement'!D21 -> -89.8712 | E17: ='Income Statement'!F21-'Income Statement'!E21 -> 73.18784 | F17: ='Income Statement'!G21-'Income Statement'!F21 -> 88.05412 | G17: ='Income Statement'!H21-'Income Statement'!G21 -> 105.16178 | H17: ='Income Statement'!I21-'Income Statement'!H21 -> 124.81043 | I17: ='Income Statement'!J21-'Income Statement'!I21 -> 147.33719
B18: Net Profit | C18: ='Income Statement'!D22-'Income Statement'!C22 -> 41 | D18: ='Income Statement'!E22-'Income Statement'!D22 -> 143.5152 | E18: ='Income Statement'!F22-'Income Statement'!E22 -> 292.75136 | F18: ='Income Statement'!G22-'Income Statement'!F22 -> 352.21648 | G18: ='Income Statement'!H22-'Income Statement'!G22 -> 420.64711 | H18: ='Income Statement'!I22-'Income Statement'!H22 -> 499.2417 | I18: ='Income Statement'!J22-'Income Statement'!I22 -> 589.34874
B21: % Variance
B22: Line Item | C22: 2023A - 2024A | D22: 2024A - 2025P | E22: 2025P - 2026P | F22: 2026P - 2027P | G22: 2027P - 2028P | H22: 2028P - 2029P | I22: 2029P - 2030P
B23: Sales | C23: =IFERROR(('Income Statement'!D8-'Income Statement'!C8)/ABS('Income Statement'!C8),"n/m") -> 0.016028147 | D23: =IFERROR(('Income Statement'!E8-'Income Statement'!D8)/ABS('Income Statement'!D8),"n/m") -> 0.1 | E23: =IFERROR(('Income Statement'!F8-'Income Statement'!E8)/ABS('Income Statement'!E8),"n/m") -> 0.1 | F23: =IFERROR(('Income Statement'!G8-'Income Statement'!F8)/ABS('Income Statement'!F8),"n/m") -> 0.1 | G23: =IFERROR(('Income Statement'!H8-'Income Statement'!G8)/ABS('Income Statement'!G8),"n/m") -> 0.1 | H23: =IFERROR(('Income Statement'!I8-'Income Statement'!H8)/ABS('Income Statement'!H8),"n/m") -> 0.1 | I23: =IFERROR(('Income Statement'!J8-'Income Statement'!I8)/ABS('Income Statement'!I8),"n/m") -> 0.1
B24: COGS | C24: =IFERROR(('Income Statement'!D9-'Income Statement'!C9)/ABS('Income Statement'!C9),"n/m") -> 0.011930374 | D24: =IFERROR(('Income Statement'!E9-'Income Statement'!D9)/ABS('Income Statement'!D9),"n/m") -> 0.10510244 | E24: =IFERROR(('Income Statement'!F9-'Income Statement'!E9)/ABS('Income Statement'!E9),"n/m") -> 0.078 | F24: =IFERROR(('Income Statement'!G9-'Income Statement'!F9)/ABS('Income Statement'!F9),"n/m") -> 0.07755102 | G24: =IFERROR(('Income Statement'!H9-'Income Statement'!G9)/ABS('Income Statement'!G9),"n/m") -> 0.077083333 | H24: =IFERROR(('Income Statement'!I9-'Income Statement'!H9)/ABS('Income Statement'!H9),"n/m") -> 0.076595745 | I24: =IFERROR(('Income Statement'!J9-'Income Statement'!I9)/ABS('Income Statement'!I9),"n/m") -> 0.076086957
B25: Gross Profit | C25: =IFERROR(('Income Statement'!D10-'Income Statement'!C10)/ABS('Income Statement'!C10),"n/m") -> 0.020121117 | D25: =IFERROR(('Income Statement'!E10-'Income Statement'!D10)/ABS('Income Statement'!D10),"n/m") -> 0.094944466 | E25: =IFERROR(('Income Statement'!F10-'Income Statement'!E10)/ABS('Income Statement'!E10),"n/m") -> 0.122 | F25: =IFERROR(('Income Statement'!G10-'Income Statement'!F10)/ABS('Income Statement'!F10),"n/m") -> 0.12156863 | G25: =IFERROR(('Income Statement'!H10-'Income Statement'!G10)/ABS('Income Statement'!G10),"n/m") -> 0.12115385 | H25: =IFERROR(('Income Statement'!I10-'Income Statement'!H10)/ABS('Income Statement'!H10),"n/m") -> 0.12075472 | I25: =IFERROR(('Income Statement'!J10-'Income Statement'!I10)/ABS('Income Statement'!I10),"n/m") -> 0.12037037
B26: Selling & General expenses | C26: =IFERROR(('Income Statement'!D12-'Income Statement'!C12)/ABS('Income Statement'!C12),"n/m") -> -0.0016844469 | D26: =IFERROR(('Income Statement'!E12-'Income Statement'!D12)/ABS('Income Statement'!D12),"n/m") -> 0.093392576 | E26: =IFERROR(('Income Statement'!F12-'Income Statement'!E12)/ABS('Income Statement'!E12),"n/m") -> 0.056862745 | F26: =IFERROR(('Income Statement'!G12-'Income Statement'!F12)/ABS('Income Statement'!F12),"n/m") -> 0.055102041 | G26: =IFERROR(('Income Statement'!H12-'Income Statement'!G12)/ABS('Income Statement'!G12),"n/m") -> 0.053191489 | H26: =IFERROR(('Income Statement'!I12-'Income Statement'!H12)/ABS('Income Statement'!H12),"n/m") -> 0.051111111 | I26: =IFERROR(('Income Statement'!J12-'Income Statement'!I12)/ABS('Income Statement'!I12),"n/m") -> 0.048837209
B27: EBITDA | C27: =IFERROR(('Income Statement'!D13-'Income Statement'!C13)/ABS('Income Statement'!C13),"n/m") -> 0.5 | D27: =IFERROR(('Income Statement'!E13-'Income Statement'!D13)/ABS('Income Statement'!D13),"n/m") -> -0.021035714 | E27: =IFERROR(('Income Statement'!F13-'Income Statement'!E13)/ABS('Income Statement'!E13),"n/m") -> 3.2 | F27: =IFERROR(('Income Statement'!G13-'Income Statement'!F13)/ABS('Income Statement'!F13),"n/m") -> 1.75 | G27: =IFERROR(('Income Statement'!H13-'Income Statement'!G13)/ABS('Income Statement'!G13),"n/m") -> 0.76 | H27: =IFERROR(('Income Statement'!I13-'Income Statement'!H13)/ABS('Income Statement'!H13),"n/m") -> 0.5125 | I27: =IFERROR(('Income Statement'!J13-'Income Statement'!I13)/ABS('Income Statement'!I13),"n/m") -> 0.4
B28: EBIT | C28: =IFERROR(('Income Statement'!D16-'Income Statement'!C16)/ABS('Income Statement'!C16),"n/m") -> 0.5 | D28: =IFERROR(('Income Statement'!E16-'Income Statement'!D16)/ABS('Income Statement'!D16),"n/m") -> -0.021035714 | E28: =IFERROR(('Income Statement'!F16-'Income Statement'!E16)/ABS('Income Statement'!E16),"n/m") -> 3.2 | F28: =IFERROR(('Income Statement'!G16-'Income Statement'!F16)/ABS('Income Statement'!F16),"n/m") -> 1.75 | G28: =IFERROR(('Income Statement'!H16-'Income Statement'!G16)/ABS('Income Statement'!G16),"n/m") -> 0.76 | H28: =IFERROR(('Income Statement'!I16-'Income Statement'!H16)/ABS('Income Statement'!H16),"n/m") -> 0.5125 | I28: =IFERROR(('Income Statement'!J16-'Income Statement'!I16)/ABS('Income Statement'!I16),"n/m") -> 0.4
B29: Interest Expense | C29: =IFERROR(('Income Statement'!D17-'Income Statement'!C17)/ABS('Income Statement'!C17),"n/m") -> 0.30967742 | D29: =IFERROR(('Income Statement'!E17-'Income Statement'!D17)/ABS('Income Statement'!D17),"n/m") -> -0.13793103 | E29: =IFERROR(('Income Statement'!F17-'Income Statement'!E17)/ABS('Income Statement'!E17),"n/m") -> 0 | F29: =IFERROR(('Income Statement'!G17-'Income Statement'!F17)/ABS('Income Statement'!F17),"n/m") -> 0 | G29: =IFERROR(('Income Statement'!H17-'Income Statement'!G17)/ABS('Income Statement'!G17),"n/m") -> 0 | H29: =IFERROR(('Income Statement'!I17-'Income Statement'!H17)/ABS('Income Statement'!H17),"n/m") -> 0 | I29: =IFERROR(('Income Statement'!J17-'Income Statement'!I17)/ABS('Income Statement'!I17),"n/m") -> 0
B30: EBT | C30: =IFERROR(('Income Statement'!D19-'Income Statement'!C19)/ABS('Income Statement'!C19),"n/m") -> 0.029962547 | D30: =IFERROR(('Income Statement'!E19-'Income Statement'!D19)/ABS('Income Statement'!D19),"n/m") -> 0.10355985 | E30: =IFERROR(('Income Statement'!F19-'Income Statement'!E19)/ABS('Income Statement'!E19),"n/m") -> 0.78805744 | F30: =IFERROR(('Income Statement'!G19-'Income Statement'!F19)/ABS('Income Statement'!F19),"n/m") -> 4.4735309 | G30: =IFERROR(('Income Statement'!H19-'Income Statement'!G19)/ABS('Income Statement'!G19),"n/m") -> 1.5381104 | H30: =IFERROR(('Income Statement'!I19-'Income Statement'!H19)/ABS('Income Statement'!H19),"n/m") -> 0.71923356 | I30: =IFERROR(('Income Statement'!J19-'Income Statement'!I19)/ABS('Income Statement'!I19),"n/m") -> 0.49385172
B31: Tax | C31: =IFERROR(('Income Statement'!D21-'Income Statement'!C21)/ABS('Income Statement'!C21),"n/m") -> -1.1363636 | D31: =IFERROR(('Income Statement'!E21-'Income Statement'!D21)/ABS('Income Statement'!D21),"n/m") -> -29.957067 | E31: =IFERROR(('Income Statement'!F21-'Income Statement'!E21)/ABS('Income Statement'!E21),"n/m") -> 0.78805744 | F31: =IFERROR(('Income Statement'!G21-'Income Statement'!F21)/ABS('Income Statement'!F21),"n/m") -> 4.4735309 | G31: =IFERROR(('Income Statement'!H21-'Income Statement'!G21)/ABS('Income Statement'!G21),"n/m") -> 1.5381104 | H31: =IFERROR(('Income Statement'!I21-'Income Statement'!H21)/ABS('Income Statement'!H21),"n/m") -> 0.71923356 | I31: =IFERROR(('Income Statement'!J21-'Income Statement'!I21)/ABS('Income Statement'!I21),"n/m") -> 0.49385172
B32: Net Profit | C32: =IFERROR(('Income Statement'!D22-'Income Statement'!C22)/ABS('Income Statement'!C22),"n/m") -> 0.073741007 | D32: =IFERROR(('Income Statement'!E22-'Income Statement'!D22)/ABS('Income Statement'!D22),"n/m") -> 0.27867029 | E32: =IFERROR(('Income Statement'!F22-'Income Statement'!E22)/ABS('Income Statement'!E22),"n/m") -> 0.78805744 | F32: =IFERROR(('Income Statement'!G22-'Income Statement'!F22)/ABS('Income Statement'!F22),"n/m") -> 4.4735309 | G32: =IFERROR(('Income Statement'!H22-'Income Statement'!G22)/ABS('Income Statement'!G22),"n/m") -> 1.5381104 | H32: =IFERROR(('Income Statement'!I22-'Income Statement'!H22)/ABS('Income Statement'!H22),"n/m") -> 0.71923356 | I32: =IFERROR(('Income Statement'!J22-'Income Statement'!I22)/ABS('Income Statement'!I22),"n/m") -> 0.49385172

Sheet Budget
B3: Sky Limited Company
B5: Budget
B9: 2025 Budget vs. Actual | H9: 2026 Budget vs. Actual
B10: Line Item | C10: Budget ($) | D10: Actual ($) | E10: $ Variance | F10: % Variance | H10: Line Item | I10: Budget ($) | J10: Actual ($) | K10: $ Variance | L10: % Variance
B11: Sales | C11: ='Income Statement'!E8 -> 11435.6 | E11: =IF(D11="","-",D11-C11) -> - | F11: =IF(D11="","-",IFERROR((D11-C11)/ABS(C11),"n/m")) -> - | H11: Sales | I11: ='Income Statement'!F8 -> 12579.16 | K11: =IF(J11="","-",J11-I11) -> - | L11: =IF(J11="","-",IFERROR((J11-I11)/ABS(I11),"n/m")) -> -
B12: COGS | C12: ='Income Statement'!E9 -> 5717.8 | E12: =IF(D12="","-",D12-C12) -> - | F12: =IF(D12="","-",IFERROR((D12-C12)/ABS(C12),"n/m")) -> - | H12: COGS | I12: ='Income Statement'!F9 -> 6163.7884 | K12: =IF(J12="","-",J12-I12) -> - | L12: =IF(J12="","-",IFERROR((J12-I12)/ABS(I12),"n/m")) -> -
B13: Gross Profit | C13: ='Income Statement'!E10 -> 5717.8 | E13: =IF(D13="","-",D13-C13) -> - | F13: =IF(D13="","-",IFERROR((D13-C13)/ABS(C13),"n/m")) -> - | H13: Gross Profit | I13: ='Income Statement'!F10 -> 6415.3716 | K13: =IF(J13="","-",J13-I13) -> - | L13: =IF(J13="","-",IFERROR((J13-I13)/ABS(I13),"n/m")) -> -
B14: Selling & General expenses | C14: ='Income Statement'!E12 -> 5832.156 | E14: =IF(D14="","-",D14-C14) -> - | F14: =IF(D14="","-",IFERROR((D14-C14)/ABS(C14),"n/m")) -> - | H14: Selling & General expenses | I14: ='Income Statement'!F12 -> 6163.7884 | K14: =IF(J14="","-",J14-I14) -> - | L14: =IF(J14="","-",IFERROR((J14-I14)/ABS(I14),"n/m")) -> -
B15: EBITDA | C15: ='Income Statement'!E13 -> -114.356 | E15: =IF(D15="","-",D15-C15) -> - | F15: =IF(D15="","-",IFERROR((D15-C15)/ABS(C15),"n/m")) -> - | H15: EBITDA | I15: ='Income Statement'!F13 -> 251.5832 | K15: =IF(J15="","-",J15-I15) -> - | L15: =IF(J15="","-",IFERROR((J15-I15)/ABS(I15),"n/m")) -> -
B16: EBIT | C16: ='Income Statement'!E16 -> -114.356 | E16: =IF(D16="","-",D16-C16) -> - | F16: =IF(D16="","-",IFERROR((D16-C16)/ABS(C16),"n/m")) -> - | H16: EBIT | I16: ='Income Statement'!F16 -> 251.5832 | K16: =IF(J16="","-",J16-I16) -> - | L16: =IF(J16="","-",IFERROR((J16-I16)/ABS(I16),"n/m")) -> -
B17: Interest Expense | C17: ='Income Statement'!E17 -> 350 | E17: =IF(D17="","-",D17-C17) -> - | F17: =IF(D17="","-",IFERROR((D17-C17)/ABS(C17),"n/m")) -> - | H17: Interest Expense | I17: ='Income Statement'!F17 -> 350 | K17: =IF(J17="","-",J17-I17) -> - | L17: =IF(J17="","-",IFERROR((J17-I17)/ABS(I17),"n/m")) -> -
B18: EBT | C18: ='Income Statement'!E19 -> -464.356 | E18: =IF(D18="","-",D18-C18) -> - | F18: =IF(D18="","-",IFERROR((D18-C18)/ABS(C18),"n/m")) -> - | H18: EBT | I18: ='Income Statement'!F19 -> -98.4168 | K18: =IF(J18="","-",J18-I18) -> - | L18: =IF(J18="","-",IFERROR((J18-I18)/ABS(I18),"n/m")) -> -
B19: Tax | C19: ='Income Statement'!E21 -> -92.8712 | E19: =IF(D19="","-",D19-C19) -> - | F19: =IF(D19="","-",IFERROR((D19-C19)/ABS(C19),"n/m")) -> - | H19: Tax | I19: ='Income Statement'!F21 -> -19.68336 | K19: =IF(J19="","-",J19-I19) -> - | L19: =IF(J19="","-",IFERROR((J19-I19)/ABS(I19),"n/m")) -> -
B20: Net Profit | C20: ='Income Statement'!E22 -> -371.4848 | E20: =IF(D20="","-",D20-C20) -> - | F20: =IF(D20="","-",IFERROR((D20-C20)/ABS(C20),"n/m")) -> - | H20: Net Profit | I20: ='Income Statement'!F22 -> -78.73344 | K20: =IF(J20="","-",J20-I20) -> - | L20: =IF(J20="","-",IFERROR((J20-I20)/ABS(I20),"n/m")) -> -
